Workbook

Sheet 塗裝各項不良率-明細
A1: 10/23起使用無毒(除了15%纖維) | I1: 8/2、8/5、8/7起關456 | K1: 8/20(E2、E3後段30度) | M1: 8/20起除了愛信80度54分其餘80度20分，8/26~9/51後段40，9/8:E6開40度
A2: 12/10-3310擦拭驗證 | I2: 11/10開始無E6(已拆除)
A3: 12/16-3310擦拭驗證
A5: 噴塗日 | B5: 噴塗 時間 | C5: 檢查日 | D5: 顏色 代碼 | E5: 漆廠 | F5: 顏色 | G5: 工單 | H5: 物料 | I5: 舊物料 | J5: 工單數量 | K5: 不良數 | L5: 總不良率 | M5: 砂礫 | N5: 毛屑 | O5: 白點 | P5: 備註 | Q5: 備註 右(R) 左(L) | R5: 來料不良 | S5: 流漆 | T5: 遮蔽治具噴飛 | U5: 其他不良 | V5: 色差 | W5: 翻車不良 | X5: 針孔 | Y5: 凹痕 | Z5: 元件
C6: 45659 | D6: =RIGHT(I6,3) -> QRB | E6: =VLOOKUP(D:D,工作表2!A:B,2,0) -> 邦善 | F6: =VLOOKUP(D:D,工作表2!A:C,3,0) -> 霧面黑 | G6: 10232655 | H6: A3252820T | I6: 5OEG006036XAHQRB | J6: 9310 | K6: 808 | L6: =K6/J6 -> 0.0867884 | M6: 560 | N6: 88 | O6: 160
C7: 45659 | D7: QSB | E7: 邦善 | F7: 黑 | G7: 10232663 | H7: A3252810T | I7: 5OEG006036XAHQSB | J7: 7182 | K7: 669 | L7: =K7/J7 -> 0.093149541 | M7: 619 | N7: 50
C8: 45659 | D8: X8A | E8: 邦善 | F8: 灰 | G8: 10237260 | H8: A33237A0T | I8: 5OEG006037XAHX8A | J8: 50 | K8: 13 | L8: =K8/J8 -> 0.26 | M8: 10 | N8: 3
C9: 45659 | D9: NQB | E9: 邦善 | F9: 黑 | G9: 10224999 | H9: A3271350T | I9: 5PPG006940XA0NQB | J9: 520 | K9: 75 | L9: =K9/J9 -> 0.14423077 | M9: 63 | N9: 12 | Q9: =VLOOKUP(H:H,'[1]雷雕處遮蔽&艾仕得8844'!$A:$C,3,0) -> L
C10: 45659 | D10: NQB | E10: 邦善 | F10: 黑 | G10: 10225000 | H10: A3271450T | I10: 5PPG006941XA0NQB | J10: 560 | K10: 84 | L10: =K10/J10 -> 0.15 | M10: 64 | N10: 20 | Q10: =VLOOKUP(H:H,'[1]雷雕處遮蔽&艾仕得8844'!$A:$C,3,0) -> R
C11: 45659 | D11: NGW | E11: 邦善 | F11: 白 | G11: 10225004 | H11: A3271830T | I11: 5PPG006943XA0NGW | J11: 440 | K11: 45 | L11: =K11/J11 -> 0.10227273 | M11: 36 | N11: 9 | Q11: =VLOOKUP(H:H,'[1]雷雕處遮蔽&艾仕得8844'!$A:$C,3,0) -> R
C12: 45659 | D12: QFA | E12: 邦善 | F12: 灰 | G12: 10225001 | H12: A3271540T | I12: 5PPG006944XA0QFA | J12: 240 | K12: 10 | L12: =K12/J12 -> 0.041666667 | M12: 8 | N12: 2 | Q12: =VLOOKUP(H:H,'[1]雷雕處遮蔽&艾仕得8844'!$A:$C,3,0) -> L
C13: 45659 | D13: NGW | E13: 邦善 | F13: 白 | G13: 10225003 | H13: A3271630T | I13: 5PPG006945XA0NGW | J13: 440 | K13: 69 | L13: =K13/J13 -> 0.15681818 | M13: 63 | N13: 6 | Q13: =VLOOKUP(H:H,'[1]雷雕處遮蔽&艾仕得8844'!$A:$C,3,0) -> R
C14: 45659 | D14: NGW | E14: 邦善 | F14: 白 | G14: 10224994 | H14: A3268570T | I14: 5PPG006970XA0NGW | J14: 520 | K14: 32 | L14: =K14/J14 -> 0.061538462 | M14: 30 | N14: 2 | Q14: =VLOOKUP(H:H,'[1]雷雕處遮蔽&艾仕得8844'!$A:$C,3,0) -> R
C15: 45659 | D15: N8B | E15: 建榮 | F15: 霧面黑 | G15: 10224872 | H15: A32474B0T | I15: 5PPG105301XC0N8B | J15: 1742 | K15: 118 | L15: =K15/J15 -> 0.067738232 | M15: 90 | N15: 28 | Q15: =VLOOKUP(H:H,'[1]雷雕處遮蔽&艾仕得8844'!$A:$C,3,0) -> 0度頭蓋
C16: 45659 | D16: NGW | E16: 邦善 | F16: 白 | G16: 10224879 | H16: A3247490T | I16: 5PPG105301XC0NGW | J16: 4020 | K16: 942 | L16: =K16/J16 -> 0.23432836 | M16: 800 | N16: 142 | Q16: =VLOOKUP(H:H,'[1]雷雕處遮蔽&艾仕得8844'!$A:$C,3,0) -> 0度頭蓋
C17: 45659 | D17: R7A | E17: 邦善 | F17: 灰 | G17: 10224888 | H17: A32474M0T | I17: 5PPG105301XC0R7A | J17: 1177 | K17: 35 | L17: =K17/J17 -> 0.029736619 | M17: 27 | N17: 8 | Q17: =VLOOKUP(H:H,'[1]雷雕處遮蔽&艾仕得8844'!$A:$C,3,0) -> 0度頭蓋
C18: 45659 | D18: UUS | E18: 邦善 | F18: 銀 | G18: 10224889 | H18: A32474N0T | I18: 5PPG105301XC0UUS | J18: 1340 | K18: 87 | L18: =K18/J18 -> 0.064925373 | M18: 70 | N18: 17 | Q18: =VLOOKUP(H:H,'[1]雷雕處遮蔽&艾仕得8844'!$A:$C,3,0) -> 0度頭蓋
C19: 45660 | D19: =RIGHT(I19,3) -> QRB | E19: =VLOOKUP(D:D,工作表2!A:B,2,0) -> 邦善 | F19: =VLOOKUP(D:D,工作表2!A:C,3,0) -> 霧面黑 | G19: 10232655 | H19: A3252820T | I19: 5OEG006036XAHQRB | J19: 19950 | K19: 1732 | L19: =K19/J19 -> 0.086817043 | M19: 1275 | N19: 256 | O19: 201
C20: 45660 | D20: =RIGHT(I20,3) -> QRB | E20: =VLOOKUP(D:D,工作表2!A:B,2,0) -> 邦善 | F20: =VLOOKUP(D:D,工作表2!A:C,3,0) -> 霧面黑 | G20: 10232654 | H20: A3252820T | I20: 5OEG006036XAHQRB | J20: 29260 | K20: 3676 | L20: =K20/J20 -> 0.12563226 | M20: 3237 | N20: 210 | O20: 229
C21: 45660 | D21: =RIGHT(I21,3) -> 75W | E21: =VLOOKUP(D:D,工作表2!A:B,2,0) -> 敦陽 | F21: =VLOOKUP(D:D,工作表2!A:C,3,0) -> 白 | G21: 10236992 | H21: A3214510T | I21: 5OET005635XAH75W | J21: 30 | K21: 11 | L21: =K21/J21 -> 0.36666667 | M21: 7 | N21: 4
C22: 45660 | D22: =RIGHT(I22,3) -> NGW | E22: =VLOOKUP(D:D,工作表2!A:B,2,0) -> 邦善 | F22: =VLOOKUP(D:D,工作表2!A:C,3,0) -> 白 | G22: 10226678 | H22: A3266410T | I22: 5PPG006948XA0NGW | J22: 640 | K22: 84 | L22: =K22/J22 -> 0.13125 | M22: 57 | N22: 27 | Q22: =VLOOKUP(H:H,'[1]雷雕處遮蔽&艾仕得8844'!$A:$C,3,0) -> R
C23: 45660 | D23: =RIGHT(I23,3) -> RCA | E23: =VLOOKUP(D:D,工作表2!A:B,2,0) -> 邦善 | F23: =VLOOKUP(D:D,工作表2!A:C,3,0) -> 灰 | G23: 10224990 | H23: A3266470T | I23: 5PPG006948XA0RCA | J23: 600 | K23: 25 | L23: =K23/J23 -> 0.041666667 | M23: 22 | N23: 3 | Q23: =VLOOKUP(H:H,'[1]雷雕處遮蔽&艾仕得8844'!$A:$C,3,0) -> R
C24: 45660 | D24: =RIGHT(I24,3) -> NCB | E24: =VLOOKUP(D:D,工作表2!A:B,2,0) -> 邦善 | F24: =VLOOKUP(D:D,工作表2!A:C,3,0) -> 黑 | G24: 10224993 | H24: A3268540T | I24: 5PPG006970XA0NCB | J24: 530 | K24: 132 | L24: =K24/J24 -> 0.2490566 | M24: 117 | N24: 15 | Q24: =VLOOKUP(H:H,'[1]雷雕處遮蔽&艾仕得8844'!$A:$C,3,0) -> R
C25: 45660 | D25: =RIGHT(I25,3) -> NEA | E25: =VLOOKUP(D:D,工作表2!A:B,2,0) -> 邦善 | F25: =VLOOKUP(D:D,工作表2!A:C,3,0) -> 灰 | G25: 10224997 | H25: A3268650T | I25: 5PPG006971XA0NEA | J25: 800 | K25: 52 | L25: =K25/J25 -> 0.065 | M25: 39 | N25: 13 | Q25: =VLOOKUP(H:H,'[1]雷雕處遮蔽&艾仕得8844'!$A:$C,3,0) -> L
C26: 45660 | D26: =RIGHT(I26,3) -> NGW | E26: =VLOOKUP(D:D,工作表2!A:B,2,0) -> 邦善 | F26: =VLOOKUP(D:D,工作表2!A:C,3,0) -> 白 | G26: 10224998 | H26: A3268670T | I26: 5PPG006971XA0NGW | J26: 800 | K26: 56 | L26: =K26/J26 -> 0.07 | M26: 56 | Q26: =VLOOKUP(H:H,'[1]雷雕處遮蔽&艾仕得8844'!$A:$C,3,0) -> L
C27: 45660 | D27: =RIGHT(I27,3) -> NEA | E27: =VLOOKUP(D:D,工作表2!A:B,2,0) -> 邦善 | F27: =VLOOKUP(D:D,工作表2!A:C,3,0) -> 灰 | G27: 10224955 | H27: A3247410T | I27: 5PPG105301XC0NEA | J27: 1742 | K27: 157 | L27: =K27/J27 -> 0.090126292 | M27: 115 | N27: 42 | Q27: =VLOOKUP(H:H,'[1]雷雕處遮蔽&艾仕得8844'!$A:$C,3,0) -> 0度頭蓋
C28: 45660 | D28: =RIGHT(I28,3) -> BBB | E28: =VLOOKUP(D:D,工作表2!A:B,2,0) -> 邦善 | F28: =VLOOKUP(D:D,工作表2!A:C,3,0) -> 霧面黑 | G28: 10236993 | H28: A30008K3T | I28: 5SNT000008XA0BBB | J28: 30 | K28: 1 | L28: =K28/J28 -> 0.033333333 | M28: 1
C29: 45660 | D29: =RIGHT(I29,3) -> 42W | E29: =VLOOKUP(D:D,工作表2!A:B,2,0) -> 敦陽 | F29: =VLOOKUP(D:D,工作表2!A:C,3,0) -> 白 | G29: 10232671 | H29: A3001920T | I29: 5SNT000019XA042W | J29: 30 | K29: 6 | L29: =K29/J29 -> 0.2 | M29: 4 | N29: 2
C30: 45661 | D30: =RIGHT(I30,3) -> QRB | E30: =VLOOKUP(D:D,工作表2!A:B,2,0) -> 邦善 | F30: =VLOOKUP(D:D,工作表2!A:C,3,0) -> 霧面黑 | G30: 10232656 | H30: A3252820T | I30: 5OEG006036XAHQRB | J30: 15960 | K30: 1441 | L30: =K30/J30 -> 0.090288221 | M30: 900 | N30: 186 | O30: 355
C31: 45661 | D31: =RIGHT(I31,3) -> QUW | E31: =VLOOKUP(D:D,工作表2!A:B,2,0) -> 邦善 | F31: =VLOOKUP(D:D,工作表2!A:C,3,0) -> 白 | G31: 10235643 | H31: A3252870T | I31: 5OEG006036XAHQUW | J31: 9842 | K31: 514 | L31: =K31/J31 -> 0.052225157 | M31: 491 | N31: 23
C32: 45661 | D32: =RIGHT(I32,3) -> W3B | E32: =VLOOKUP(D:D,工作表2!A:B,2,0) -> 華山 | F32: =VLOOKUP(D:D,工作表2!A:C,3,0) -> 黑 | G32: 10237527 | H32: A3297330T | I32: 5OEG006116XAHW3B | J32: 30 | K32: 6 | L32: =K32/J32 -> 0.2 | M32: 6
C33: 45661 | D33: =RIGHT(I33,3) -> VYW | E33: =VLOOKUP(D:D,工作表2!A:B,2,0) -> 華山 | F33: =VLOOKUP(D:D,工作表2!A:C,3,0) -> 白 | G33: 10226624 | H33: A3297420T | I33: 5OEG006117XAHVYW | J33: 770 | K33: 156 | L33: =K33/J33 -> 0.2025974 | M33: 112 | N33: 44
C34: 45661 | D34: =RIGHT(I34,3) -> WAA | E34: =VLOOKUP(D:D,工作表2!A:B,2,0) -> 華山 | F34: =VLOOKUP(D:D,工作表2!A:C,3,0) -> 灰 | G34: 10226626 | H34: A3297470T | I34: 5OEG006117XAHWAA | J34: 560 | K34: 140 | L34: =K34/J34 -> 0.25 | M34: 95 | N34: 45
C35: 45661 | D35: =RIGHT(I35,3) -> N8B | E35: =VLOOKUP(D:D,工作表2!A:B,2,0) -> 邦善 | F35: =VLOOKUP(D:D,工作表2!A:C,3,0) -> 霧面黑 | G35: 10224052 | H35: A3228650T | I35: 5OET005693XCHN8B | J35: 6118 | K35: 232 | L35: =K35/J35 -> 0.037920889 | M35: 207 | N35: 25
C36: 45661 | D36: =RIGHT(I36,3) -> N8B | E36: =VLOOKUP(D:D,工作表2!A:B,2,0) -> 邦善 | F36: =VLOOKUP(D:D,工作表2!A:C,3,0) -> 霧面黑 | G36: 10224979 | H36: A3228650T | I36: 5OET005693XCHN8B | J36: 1862 | K36: 112 | L36: =K36/J36 -> 0.060150376 | M36: 98 | N36: 14
C37: 45661 | D37: =RIGHT(I37,3) -> NBB | E37: =VLOOKUP(D:D,工作表2!A:B,2,0) -> 邦善 | F37: =VLOOKUP(D:D,工作表2!A:C,3,0) -> 霧面黑 | G37: 10227968 | H37: A32286N0T | I37: 5OET005693XCHNBB | J37: 1862 | K37: 37 | L37: =K37/J37 -> 0.019871106 | M37: 35 | N37: 2
C38: 45661 | D38: =RIGHT(I38,3) -> VPL | E38: =VLOOKUP(D:D,工作表2!A:B,2,0) -> 邦善 | F38: =VLOOKUP(D:D,工作表2!A:C,3,0) -> 藍 | G38: 10224982 | H38: A32286A1T | I38: 5OET005693XCHVPL | J38: 798 | K38: 58 | L38: =K38/J38 -> 0.072681704 | M38: 55 | N38: 3
C39: 45661 | D39: =RIGHT(I39,3) -> NGW | E39: =VLOOKUP(D:D,工作表2!A:B,2,0) -> 邦善 | F39: =VLOOKUP(D:D,工作表2!A:C,3,0) -> 白 | G39: 10224985 | H39: A3266310T | I39: 5PPG006947XA0NGW | J39: 640 | K39: 33 | L39: =K39/J39 -> 0.0515625 | M39: 30 | N39: 3 | Q39: =VLOOKUP(H:H,'[1]雷雕處遮蔽&艾仕得8844'!$A:$C,3,0) -> L
C40: 45661 | D40: =RIGHT(I40,3) -> RCA | E40: =VLOOKUP(D:D,工作表2!A:B,2,0) -> 邦善 | F40: =VLOOKUP(D:D,工作表2!A:C,3,0) -> 灰 | G40: 10224986 | H40: A3266370T | I40: 5PPG006947XA0RCA | J40: 330 | K40: 34 | L40: =K40/J40 -> 0.1030303 | M40: 26 | N40: 8 | Q40: =VLOOKUP(H:H,'[1]雷雕處遮蔽&艾仕得8844'!$A:$C,3,0) -> L
C41: 45661 | D41: =RIGHT(I41,3) -> RRA | E41: =VLOOKUP(D:D,工作表2!A:B,2,0) -> 邦善 | F41: =VLOOKUP(D:D,工作表2!A:C,3,0) -> 灰 | G41: 10224987 | H41: A3266380T | I41: 5PPG006947XA0RRA | J41: 680 | K41: 46 | L41: =K41/J41 -> 0.067647059 | M41: 40 | N41: 6 | Q41: =VLOOKUP(H:H,'[1]雷雕處遮蔽&艾仕得8844'!$A:$C,3,0) -> L
...

Sheet 工作表2
A1: 1:邦善 | B1: 2.建榮 | C1: 3.敦陽 | F1: 霧面黑 | G1: 銀 | H1: 白 | I1: 灰 | J1: 紅 | K1: 黑 | L1: 藍 | M1: 綠 | N1: 金 | O1: 棕 | P1: 黃 | Q1: 紫 | R1: 橘
A2: 76S | B2: 敦陽 | C2: 銀 | D2: PT00047500T
A3: 4PW | B3: 敦陽 | C3: 白 | D3: PT00001700T
A4: 4VW | B4: 建榮 | C4: 白 | D4: PT00002100T
A5: 75W | B5: 敦陽 | C5: 白 | D5: PT00047400T
A6: 76S | B6: 敦陽 | C6: 銀 | D6: PT00047500T
A7: 78A | B7: 敦陽 | C7: 灰 | D7: PT00047600T
A8: 88S | B8: 敦陽 | C8: 銀 | D8: PT00048000T
A9: 9DB | B9: 敦陽 | C9: 黑 | D9: PT00015200T
A10: AAW | B10: 邦善 | C10: 白 | D10: PT00000800T
A11: FHW | B11: 建榮 | C11: 白 | D11: PT00050000T
A12: HSS | B12: 邦善 | C12: 銀 | D12: PT00111600T
A13: HUR | B13: 建榮 | C13: 紅 | D13: PT00111700T
... A59: HSS | B59: 邦善 | C59: 銀 | D59: PT00111600T
A60: A0T | B60: 建榮 | C60: 底漆
A61: MUB | B61: 邦善 | C61: 黑 | D61: PT00109500T
A62: QEN | B62: 邦善 | C62: 棕 | D62: PT00128600T
A63: V9L | B63: 邦善 | C63: 藍 | D63: PT00154100T
A64: 2US | B64: 建榮 | C64: 銀 | D64: PT00006700T
A65: M2W | B65: 邦善 | C65: 白 | D65: PT00105700T
A66: 71A | B66: 敦陽 | C66: 灰 | D66: PT00003000T
A67: CCA | B67: 邦善 | C67: 灰 | D67: PT00030800T
A68: 39A | B68: 敦陽 | C68: 灰 | D68: =VLOOKUP(A68,[1]色碼對照!$G:$I,3,0) -> #N/A
A69: 4BB | B69: 敦陽 | C69: 黑 | D69: =VLOOKUP(A69,[1]色碼對照!$G:$I,3,0) -> #N/A
A70: 7FB | B70: 邦善 | C70: 黑 | D70: =VLOOKUP(A70,[1]色碼對照!$G:$I,3,0) -> #N/A
A71: ACS | B71: 建榮 | C71: 銀 | D71: =VLOOKUP(A71,[1]色碼對照!$G:$I,3,0) -> #N/A
A72: 6XB | B72: 邦善 | C72: 霧面黑 | D72: =VLOOKUP(A72,[1]色碼對照!$G:$I,3,0) -> #N/A
A73: BBB | B73: 邦善 | C73: 霧面黑 | D73: =VLOOKUP(A73,[1]色碼對照!$G:$I,3,0) -> #N/A
A74: HDL | B74: 邦善 | C74: 藍 | D74: =VLOOKUP(A74,[1]色碼對照!$G:$I,3,0) -> #N/A
A75: QRB | B75: 邦善 | C75: 霧面黑
A76: 31B | B76: 建榮 | C76: 黑
A77: EEA | B77: 建榮 | C77: 灰
A78: N4L | B78: 邦善 | C78: 藍
A79: 09B | B79: 邦善 | C79: 黑
A80: VLS | B80: 邦善 | C80: 銀
A81: NJR | B81: 邦善 | C81: 紅
A82: S3B | B82: 邦善 | C82: 黑
A83: VBR | B83: 邦善 | C83: 紅
A84: QUW | B84: 邦善 | C84: 白
A85: QXR | B85: 邦善 | C85: 紅
...

Sheet 工作表3
A2: PT00000800T | B2: 邦善
A3: PT00001700T | B3: 敦陽
A4: PT00002100T | B4: 建榮
A5: PT00015200T | B5: 敦陽
A6: PT00047400T | B6: 敦陽
A7: PT00047500T | B7: 敦陽
A8: PT00047600T | B8: 敦陽
A9: PT00048000T | B9: 敦陽
A10: PT00050000T | B10: 建榮
A11: PT00106000T | B11: 邦善
A12: PT00111600T | B12: 邦善
A13: PT00111700T | B13: 建榮
... A65: PT00055600T | B65: 邦善

Sheet 工作表1
C2: 漆廠 | D2: 顏色 | E2: 工單 | F2: 物料 | G2: 舊物料 | H2: 工單數量 | I2: 不良數 | J2: 總不良率 | K2: 砂礫 不良率 | L2: 毛屑 不良率
A3: 45811 | B3: S3B | C3: 邦善 | D3: 黑 | E3: 10263212 | F3: A32528G0T | G3: 5OEG006036XAHS3B | H3: 2128 | I3: 254 | J3: 0.1193609 | K3: 250 | L3: 4
A4: 45817 | B4: S3B | C4: 邦善 | D4: 黑 | E4: 10267029 | F4: A32528G0T | G4: 5OEG006036XAHS3B | H4: 2128 | I4: 123 | J4: 0.057800752 | K4: 117 | L4: 6
A5: 45828 | B5: S3B | C5: 邦善 | D5: 黑 | E5: 10263213 | F5: A32528G0T | G5: 5OEG006036XAHS3B | H5: 9044 | I5: 1031 | J5: 0.11399823 | K5: 1001 | L5: 30
B8: 底漆 | E8: 面漆 | H8: 金油
B9: 底漆型號 | C9: 硬化劑 | D9: 稀釋劑 | E9: 面漆型號 | F9: 硬化劑 | G9: 稀釋劑 | H9: 金油型號 | I9: 硬化劑 | J9: 稀釋劑 | K9: 溫度℃ | L9: 濕度%
A10: 45811 | B10: 840RVS5 | C10: 845R | D10: AU370 | E10: NH-547 | F10: AK260 | G10: AB385 | H10: G27800 | I10: XB387 | J10: AK261 | K10: 29.9 | L10: 58
A11: 45817 | B11: 840RVS5 | C11: 845R | D11: AU370 | E11: NH-547 | F11: AK260 | G11: AB385 | H11: G27800 | I11: XB387 | J11: AK261 | K11: 30.9 | L11: 67
A12: 45828 | B12: 840RVS5 | C12: 845R | D12: AU370 | E12: NH-547 | F12: AK260 | G12: AB385 | H12: G27800 | I12: XB387 | J12: AK261 | K12: 29.8 | L12: 59

Sheet 工作表4
B1: 底漆 | E1: 面漆 | I1: 金油
B2: 底漆型號 | C2: 硬化劑 | D2: 稀釋劑 | E2: 面漆型號 | F2: 用量g | G2: 硬化劑 | H2: 稀釋劑 | I2: 金油型號 | J2: 硬化劑 | K2: 稀釋劑
A3: 45811 | B3: 840RVS5 | C3: 845R | D3: AU370 | E3: NH-547 | F3: 400 | G3: AK260 | H3: AB385 | I3: G27800 | J3: AK261 | K3: XB387
A4: 45817 | B4: 840RVS5 | C4: 845R | D4: AU370 | E4: NH-547 | F4: 600 | G4: AK260 | H4: AB385 | I4: G27800 | J4: AK261 | K4: XB387
A5: 45828 | B5: 840RVS5 | C5: 845R | D5: AU370 | E5: NH-547 | F5: 2300 | G5: AK260 | H5: AB385 | I5: G27800 | J5: AK261 | K5: XB387
A9: 45846 | B9: 45847 | C9: UUS | D9: 邦善 | E9: 銀 | F9: 10264802 | G9: A3266490T | H9: 5PPG006948XA0UUS | I9: 120 | J9: 1 | K9: 0.0083333333 | L9: 1 | M9: E1*40 | R9: 4826
A10: 45846 | B10: 45848 | C10: UUS | D10: 邦善 | E10: 銀 | F10: 10263296 | G10: A32977A0T | H10: 5PPG007034XA0UUS | I10: 160 | J10: 4 | K10: 0.025 | L10: 4 | M10: E1*40 | R10: 5223
A11: 45846 | B11: 45848 | C11: UUS | D11: 邦善 | E11: 銀 | F11: 10263297 | G11: A32981A0T | H11: 5PPG007039XA0UUS | I11: 200 | J11: 3 | K11: 0.015 | L11: 3 | M11: E1*40 | R11: 5228
A12: 45847 | B12: 45848 | C12: UUS | D12: 邦善 | E12: 銀 | F12: 10269091 | G12: A32474N0T | H12: 5PPG105301XC0UUS | I12: 1742 | J12: 110 | K12: 0.063145809 | L12: 98 | M12: E1*40 | N12: 12 | R12: 5301
A13: 45847 | B13: 45849 | C13: UUS | D13: 邦善 | E13: 銀 | F13: 10269136 | G13: A32801A0T | H13: 5PPG007029XA0UUS | I13: 280 | J13: 17 | K13: 0.060714286 | L13: 15 | M13: E1*40 | N13: 2 | R13: 5103
A14: 45847 | B14: 45849 | C14: UUS | D14: 邦善 | E14: 銀 | F14: 10264893 | G14: A32976A0T | H14: 5PPG007037XA0UUS | I14: 200 | J14: 9 | K14: 0.045 | L14: 7 | M14: E1*40 | N14: 2 | R14: 5226
A15: 45847 | B15: 45850 | C15: UUS | D15: 邦善 | E15: 銀 | F15: 10263243 | G15: A32799A0T | H15: 5PPG007025XA0UUS | I15: 240 | J15: 30 | K15: 0.125 | L15: 25 | M15: E1*40 | N15: 5 | R15: 5099
A16: 45847 | B16: 45850 | C16: UUS | D16: 邦善 | E16: 銀 | F16: 10267894 | G16: A32799A0T | H16: 5PPG007025XA0UUS | I16: 280 | J16: 35 | K16: 0.125 | L16: 15 | M16: E1*40 | N16: 5 | R16: 5099
A17: 45847 | B17: 45850 | C17: UUS | D17: 邦善 | E17: 銀 | F17: 10264894 | G17: A32981A0T | H17: 5PPG007039XA0UUS | I17: 280 | J17: 17 | K17: 0.060714286 | L17: 15 | M17: E1*40 | N17: 2 | R17: 5228
A24: 45980 | B24: 0.63333333 | C24: 45982 | D24: RCA | E24: 邦善 | F24: 灰 | G24: 10296759 | H24: A32592C0T | I24: 5OEG005976XAHRCA | J24: 266 | K24: 28 | L24: 0.10526316 | M24: 23 | N24: 5 | P24: E4.5關(排風全開)、E2E3後段40 | Q24: 0
A25: 45981 | B25: 0.6375 | C25: 45982 | D25: SYL | E25: 邦善 | F25: 藍 | G25: 10296764 | H25: A32592F0T | I25: 5OEG005976XAHSYL | J25: 532 | K25: 31 | L25: 0.058270677 | M25: 25 | N25: 6 | P25: E4.5關(排風全開)、E2E3後段40 | Q25: 0
A26: 45980 | B26: 0.63402778 | C26: 45982 | D26: SZR | E26: 邦善 | F26: 紅 | G26: 10296762 | H26: A32592D0T | I26: 5OEG005976XAHSZR | J26: 532 | K26: 47 | L26: 0.088345865 | M26: 40 | N26: 7 | P26: E4.5關(排風全開)、E2E3後段40 | Q26: 0
A27: 45980 | B27: 0.47638889 | C27: 45982 | D27: RZG | E27: 邦善 | F27: 綠 | G27: 10296744 | H27: A32528C0T | I27: 5OEG006036XAHRZG | J27: 3192 | K27: 167 | L27: 0.052318296 | M27: 155 | N27: 12 | P27: E4.5關(排風全開)、E2E3後段40 | Q27: 0
A28: 45981 | B28: 0.59861111 | C28: 45982 | D28: U3L | E28: 邦善 | F28: 藍 | G28: 10296740 | H28: A3252871T | I28: 5OEG006036XAHU3L | J28: 2926 | K28: 80 | L28: 0.02734108 | M28: 70 | N28: 10 | P28: E4.5關(排風全開)、E2E3後段40 | Q28: 0
A29: 45981 | B29: 0.61319444 | C29: 45982 | D29: WZL | E29: 邦善 | F29: 銀 | G29: 10296739 | H29: A3252822T | I29: 5OEG006036XAHWZL | J29: 2394 | K29: 138 | L29: 0.05764411 | M29: 120 | N29: 18 | P29: E4.5關(排風全開)、E2E3後段40 | Q29: 0
A30: 45980 | B30: 0.54166667 | C30: 45982 | D30: TZB | E30: 邦善 | F30: 黑 | G30: 10301729 | H30: A3323770T | I30: 5OEG006037XAHTZB | J30: 266 | K30: 17 | L30: 0.063909774 | M30: 15 | N30: 2 | P30: E4.5關(排風全開)、E2E3後段40 | Q30: 0
A31: 45981 | B31: 0.62083333 | C31: 45982 | D31: WZL | E31: 邦善 | F31: 銀 | G31: 10301667 | H31: A3323720T | I31: 5OEG006037XAHWZL | J31: 532 | K31: 30 | L31: 0.056390977 | M31: 20 | N31: 10 | P31: E4.5關(排風全開)、E2E3後段40 | Q31: 0
