Workbook

Sheet 塗裝各項不良率-明細
A2: 2026/1/7底漆前烘烤，無E1輸送帶
A3: 噴塗日 | B3: 噴塗 時間 | C3: 檢查日 | D3: 顏色 代碼 | E3: 漆廠 | F3: 顏色 | G3: 工單 | H3: 物料 | I3: 舊物料 | J3: 工單數量 | K3: 不良數 | L3: 總不良率 | M3: 砂礫 | N3: 毛屑 | O3: 白點 | P3: 備註 | Q3: 備註 右(R) 左(L) | R3: 來料不良 | S3: 流漆 | T3: 遮蔽治具噴飛 | U3: 其他不良 | V3: 色差 | W3: 翻車不良 | X3: 針孔 | Y3: 凹痕 | Z3: 元件
A4: 46387 | B4: 0.39027778 | C4: 46024 | D4: =RIGHT(I4,3) -> VLS | E4: =VLOOKUP(D:D,工作表2!A:B,2,0) -> 邦善 | F4: =VLOOKUP(D:D,工作表2!A:C,3,0) -> 銀 | G4: 10309279 | H4: A32528Y1T | I4: 5OEG006036XAHVLS | J4: 3458 | K4: 73 | L4: =K4/J4 -> 0.021110468 | M4: 50 | N4: 23 | P4: E4.5關(排風全開)、E2E3後段40
A5: 46387 | B5: 0.43680556 | C5: 46024 | D5: =RIGHT(I5,3) -> VWL | E5: =VLOOKUP(D:D,工作表2!A:B,2,0) -> 邦善 | F5: =VLOOKUP(D:D,工作表2!A:C,3,0) -> 藍 | G5: 10309278 | H5: A32528X1T | I5: 5OEG006036XAHVWL | J5: 266 | K5: 24 | L5: =K5/J5 -> 0.090225564 | M5: 14 | N5: 10 | P5: E4.5關(排風全開)、E2E3後段40
A6: 46387 | B6: 0.42986111 | C6: 46024 | D6: =RIGHT(I6,3) -> VXW | E6: =VLOOKUP(D:D,工作表2!A:B,2,0) -> 邦善 | F6: =VLOOKUP(D:D,工作表2!A:C,3,0) -> 白 | G6: 10309280 | H6: A32528Z1T | I6: 5OEG006036XAHVXW | J6: 798 | K6: 25 | L6: =K6/J6 -> 0.031328321 | M6: 15 | N6: 10 | P6: E4.5關(排風全開)、E2E3後段40
A7: 46387 | B7: 0.40138889 | C7: 46024 | D7: =RIGHT(I7,3) -> WZL | E7: =VLOOKUP(D:D,工作表2!A:B,2,0) -> 邦善 | F7: =VLOOKUP(D:D,工作表2!A:C,3,0) -> 銀 | G7: 10309313 | H7: A3252822T | I7: 5OEG006036XAHWZL | J7: 5054 | K7: 283 | L7: =K7/J7 -> 0.055995251 | M7: 250 | N7: 33 | P7: E4.5關(排風全開)、E2E3後段40
A8: 46387 | B8: 0.42916667 | C8: 46024 | D8: =RIGHT(I8,3) -> X8A | E8: =VLOOKUP(D:D,工作表2!A:B,2,0) -> 邦善 | F8: =VLOOKUP(D:D,工作表2!A:C,3,0) -> 灰 | G8: 10309268 | H8: A3252842T | I8: 5OEG006036XAHX8A | J8: 266 | K8: 55 | L8: =K8/J8 -> 0.20676692 | M8: 35 | N8: 20 | P8: E4.5關(排風全開)、E2E3後段40
A9: 46374 | B9: 0.63333333 | C9: 46027 | D9: =RIGHT(I9,3) -> 75W | E9: =VLOOKUP(D:D,工作表2!A:B,2,0) -> 敦陽 | F9: =VLOOKUP(D:D,工作表2!A:C,3,0) -> 白 | G9: 10309165 | H9: A3221710T | I9: 5PPG105480XA075W | J9: 238 | K9: 50 | L9: =K9/J9 -> 0.21008403 | M9: 38 | N9: 12 | P9: E4.5關(排風全開)、E2E3後段40 | Q9: 0度頭蓋
A10: 46024 | B10: 0.63680556 | C10: 46027 | D10: =RIGHT(I10,3) -> SZR | E10: =VLOOKUP(D:D,工作表2!A:B,2,0) -> 邦善 | F10: =VLOOKUP(D:D,工作表2!A:C,3,0) -> 紅 | G10: 10310881 | H10: A32592D0T | I10: 5OEG005976XAHSZR | J10: 266 | K10: 29 | L10: =K10/J10 -> 0.10902256 | M10: 21 | N10: 8 | P10: E4.5關(排風全開)、E2E3後段40
A11: 46024 | B11: 0.38263889 | C11: 46027 | D11: =RIGHT(I11,3) -> QRB | E11: =VLOOKUP(D:D,工作表2!A:B,2,0) -> 邦善 | F11: =VLOOKUP(D:D,工作表2!A:C,3,0) -> 霧面黑 | G11: 10309233 | H11: A3252820T | I11: 5OEG006036XAHQRB | J11: 17822 | K11: 900 | L11: =K11/J11 -> 0.050499383 | M11: 577 | N11: 282 | O11: 41 | P11: E4.5關(排風全開)、E2E3後段40
A12: 46385 | B12: 0.45833333 | C12: 46027 | D12: =RIGHT(I12,3) -> N8B | E12: =VLOOKUP(D:D,工作表2!A:B,2,0) -> 邦善 | F12: =VLOOKUP(D:D,工作表2!A:C,3,0) -> 霧面黑 | G12: 10304228 | H12: A3228650T | I12: 5OET005693XCHN8B | J12: 4522 | K12: 90 | L12: =K12/J12 -> 0.019902698 | M12: 80 | N12: 10 | P12: E4.5關(排風全開)、E2E3後段40
A13: 46381 | B13: 0.57847222 | C13: 46027 | D13: =RIGHT(I13,3) -> 75W | E13: =VLOOKUP(D:D,工作表2!A:B,2,0) -> 敦陽 | F13: =VLOOKUP(D:D,工作表2!A:C,3,0) -> 白 | G13: 10309167 | H13: A3225070T | I13: 5OET005831XAH75W | J13: 72 | K13: 8 | L13: =K13/J13 -> 0.11111111 | M13: 6 | N13: 2 | P13: E4.5關(排風全開)、E2E3後段40
A14: 46381 | B14: 0.57638889 | C14: 46027 | D14: =RIGHT(I14,3) -> 78A | E14: =VLOOKUP(D:D,工作表2!A:B,2,0) -> 敦陽 | F14: =VLOOKUP(D:D,工作表2!A:C,3,0) -> 灰 | G14: 10309180 | H14: A32250A0T | I14: 5OET005831XAH78A | J14: 30 | K14: 0 | L14: =K14/J14 -> 0 | P14: E4.5關(排風全開)、E2E3後段40
A15: 46381 | B15: 0.58263889 | C15: 46027 | D15: =RIGHT(I15,3) -> QDW | E15: =VLOOKUP(D:D,工作表2!A:B,2,0) -> 邦善 | F15: =VLOOKUP(D:D,工作表2!A:C,3,0) -> 白 | G15: 10304227 | H15: A32250S0T | I15: 5OET005831XAHQDW | J15: 144 | K15: 12 | L15: =K15/J15 -> 0.083333333 | M15: 10 | N15: 2 | P15: E4.5關(排風全開)、E2E3後段40
A16: 46375 | B16: 0.57152778 | C16: 46027 | D16: =RIGHT(I16,3) -> NGW | E16: =VLOOKUP(D:D,工作表2!A:B,2,0) -> 邦善 | F16: =VLOOKUP(D:D,工作表2!A:C,3,0) -> 白 | G16: 10302945 | H16: A3271530T | I16: 5PPG006944XA0NGW | J16: 480 | K16: 28 | L16: =K16/J16 -> 0.058333333 | M16: 18 | N16: 10 | P16: E4.5關(排風全開)、E2E3後段40 | Q16: L
A17: 46385 | B17: 0.55694444 | C17: 46027 | D17: =RIGHT(I17,3) -> NGW | E17: =VLOOKUP(D:D,工作表2!A:B,2,0) -> 邦善 | F17: =VLOOKUP(D:D,工作表2!A:C,3,0) -> 白 | G17: 10302947 | H17: A3279810T | I17: 5PPG007024XA0NGW | J17: 600 | K17: 73 | L17: =K17/J17 -> 0.12166667 | M17: 61 | N17: 12 | P17: E4.5關(排風全開)、E2E3後段40 | Q17: L
A18: 46385 | B18: 0.54375 | C18: 46027 | D18: =RIGHT(I18,3) -> NGW | E18: =VLOOKUP(D:D,工作表2!A:B,2,0) -> 邦善 | F18: =VLOOKUP(D:D,工作表2!A:C,3,0) -> 白 | G18: 10302948 | H18: A3279910T | I18: 5PPG007025XA0NGW | J18: 560 | K18: 57 | L18: =K18/J18 -> 0.10178571 | M18: 40 | N18: 17 | P18: E4.5關(排風全開)、E2E3後段40 | Q18: R
A19: 46381 | B19: 0.56666667 | C19: 46027 | D19: =RIGHT(I19,3) -> 78A | E19: =VLOOKUP(D:D,工作表2!A:B,2,0) -> 敦陽 | F19: =VLOOKUP(D:D,工作表2!A:C,3,0) -> 灰 | G19: 10309179 | H19: A3221740T | I19: 5PPG105480XA078A | J19: 134 | K19: 15 | L19: =K19/J19 -> 0.1119403 | M19: 12 | N19: 3 | P19: E4.5關(排風全開)、E2E3後段40 | Q19: 0度頭蓋
A20: 46381 | B20: 0.56805556 | C20: 46027 | D20: =RIGHT(I20,3) -> QDW | E20: =VLOOKUP(D:D,工作表2!A:B,2,0) -> 邦善 | F20: =VLOOKUP(D:D,工作表2!A:C,3,0) -> 白 | G20: 10304224 | H20: A32217L0T | I20: 5PPG105480XA0QDW | J20: 134 | K20: 14 | L20: =K20/J20 -> 0.10447761 | M20: 10 | N20: 4 | P20: E4.5關(排風全開)、E2E3後段40 | Q20: 0度頭蓋
A21: 46027 | B21: 0.38194444 | C21: 46028 | D21: =RIGHT(I21,3) -> QRB | E21: =VLOOKUP(D:D,工作表2!A:B,2,0) -> 邦善 | F21: =VLOOKUP(D:D,工作表2!A:C,3,0) -> 霧面黑 | G21: 10309228 | H21: A3252820T | I21: 5OEG006036XAHQRB | J21: 25802 | K21: 1214 | L21: =K21/J21 -> 0.047050616 | M21: 785 | N21: 405 | O21: 24 | P21: E4.5關(排風全開)、E2E3後段40
A22: 46024 | B22: 0.45277778 | C22: 46028 | D22: =RIGHT(I22,3) -> S3B | E22: =VLOOKUP(D:D,工作表2!A:B,2,0) -> 邦善 | F22: =VLOOKUP(D:D,工作表2!A:C,3,0) -> 黑 | G22: 10309255 | H22: A32528G0T | I22: 5OEG006036XAHS3B | J22: 5586 | K22: 529 | L22: =K22/J22 -> 0.094701038 | M22: 370 | N22: 159 | P22: E4.5關(排風全開)、E2E3後段40
A23: 46027 | B23: 0.59305556 | C23: 46028 | D23: =RIGHT(I23,3) -> NGW | E23: =VLOOKUP(D:D,工作表2!A:B,2,0) -> 邦善 | F23: =VLOOKUP(D:D,工作表2!A:C,3,0) -> 白 | G23: 10304243 | H23: A3266410T | I23: 5PPG006948XA0NGW | J23: 320 | K23: 27 | L23: =K23/J23 -> 0.084375 | M23: 19 | N23: 8 | P23: E4.5關(排風全開)、E2E3後段40 | Q23: R
A24: 46024 | B24: 0.54583333 | C24: 46028 | D24: =RIGHT(I24,3) -> NGW | E24: =VLOOKUP(D:D,工作表2!A:B,2,0) -> 邦善 | F24: =VLOOKUP(D:D,工作表2!A:C,3,0) -> 白 | G24: 10304254 | H24: A3298020T | I24: 5PPG007038XA0NGW | J24: 520 | K24: 27 | L24: =K24/J24 -> 0.051923077 | M24: 23 | N24: 4 | P24: E4.5關(排風全開)、E2E3後段40
A25: 46024 | B25: 0.54583333 | C25: 46028 | D25: =RIGHT(I25,3) -> RRA | E25: =VLOOKUP(D:D,工作表2!A:B,2,0) -> 邦善 | F25: =VLOOKUP(D:D,工作表2!A:C,3,0) -> 灰 | G25: 10304255 | H25: A3298150T | I25: 5PPG007039XA0RRA | J25: 560 | K25: 24 | L25: =K25/J25 -> 0.042857143 | M25: 20 | N25: 4 | P25: E4.5關(排風全開)、E2E3後段40
A26: 46024 | B26: 0.62638889 | C26: 46028 | D26: =RIGHT(I26,3) -> 76S | E26: =VLOOKUP(D:D,工作表2!A:B,2,0) -> 敦陽 | F26: =VLOOKUP(D:D,工作表2!A:C,3,0) -> 銀 | G26: 10309166 | H26: A3221730T | I26: 5PPG105480XA076S | J26: 134 | K26: 11 | L26: =K26/J26 -> 0.082089552 | M26: 8 | N26: 3 | P26: E4.5關(排風全開)、E2E3後段40 | Q26: 0度頭蓋
A27: 46024 | B27: 0.63125 | C27: 46028 | D27: =RIGHT(I27,3) -> 39A | E27: =VLOOKUP(D:D,工作表2!A:B,2,0) -> 敦陽 | F27: =VLOOKUP(D:D,工作表2!A:C,3,0) -> 灰 | G27: 10305406 | H27: A30003E0T | I27: 5SNT000003XA039A | J27: 30 | K27: 9 | L27: =K27/J27 -> 0.3 | M27: 7 | N27: 2 | P27: E4.5關(排風全開)、E2E3後段40
A28: 46027 | B28: 0.62152778 | C28: 46029 | D28: =RIGHT(I28,3) -> N9B | E28: =VLOOKUP(D:D,工作表2!A:B,2,0) -> 邦善 | F28: =VLOOKUP(D:D,工作表2!A:C,3,0) -> 黑 | G28: 10311375 | H28: A32592B0T | I28: 5OEG005976XAHN9B | J28: 266 | K28: 25 | L28: =K28/J28 -> 0.093984962 | M28: 15 | N28: 10 | P28: E4.5關(排風全開)、E2E3後段40
A29: 46027 | B29: 0.47708333 | C29: 46029 | D29: =RIGHT(I29,3) -> NBB | E29: =VLOOKUP(D:D,工作表2!A:B,2,0) -> 邦善 | F29: =VLOOKUP(D:D,工作表2!A:C,3,0) -> 霧面黑 | G29: 10304238 | H29: A3259220T | I29: 5OEG005976XAHNBB | J29: 798 | K29: 20 | L29: =K29/J29 -> 0.025062657 | M29: 15 | N29: 5 | P29: E4.5關(排風全開)、E2E3後段40
A30: 46027 | B30: 0.47430556 | C30: 46029 | D30: =RIGHT(I30,3) -> PLB | E30: =VLOOKUP(D:D,工作表2!A:B,2,0) -> 邦善 | F30: =VLOOKUP(D:D,工作表2!A:C,3,0) -> 霧面黑 | G30: 10309185 | H30: A32592G0T | I30: 5OEG005976XAHPLB | J30: 1064 | K30: 25 | L30: =K30/J30 -> 0.023496241 | M30: 20 | N30: 5 | P30: E4.5關(排風全開)、E2E3後段40
A31: 46027 | B31: 0.57222222 | C31: 46029 | D31: =RIGHT(I31,3) -> Q9B | E31: =VLOOKUP(D:D,工作表2!A:B,2,0) -> 邦善 | F31: =VLOOKUP(D:D,工作表2!A:C,3,0) -> 黑 | G31: 10304651 | H31: A3259270T | I31: 5OEG005976XAHQ9B | J31: 1596 | K31: 159 | L31: =K31/J31 -> 0.09962406 | M31: 119 | N31: 40 | P31: E4.5關(排風全開)、E2E3後段40
A32: 46024 | B32: 0.63333333 | C32: 46029 | D32: =RIGHT(I32,3) -> UUS | E32: =VLOOKUP(D:D,工作表2!A:B,2,0) -> 邦善 | F32: =VLOOKUP(D:D,工作表2!A:C,3,0) -> 銀 | G32: 10304242 | H32: A32592T0T | I32: 5OEG005976XAHUUS | J32: 1330 | K32: 101 | L32: =K32/J32 -> 0.07593985 | M32: 89 | N32: 12 | P32: E4.5關(排風全開)、E2E3後段40
A33: 46027 | B33: 0.53055556 | C33: 46029 | D33: =RIGHT(I33,3) -> NBB | E33: =VLOOKUP(D:D,工作表2!A:B,2,0) -> 邦善 | F33: =VLOOKUP(D:D,工作表2!A:C,3,0) -> 霧面黑 | G33: 10304231 | H33: A32286N0T | I33: 5OET005693XCHNBB | J33: 1596 | K33: 17 | L33: =K33/J33 -> 0.010651629 | M33: 14 | N33: 3 | P33: E4.5關(排風全開)、E2E3後段40
A34: 46027 | B34: 0.58125 | C34: 46029 | D34: =RIGHT(I34,3) -> NEA | E34: =VLOOKUP(D:D,工作表2!A:B,2,0) -> 邦善 | F34: =VLOOKUP(D:D,工作表2!A:C,3,0) -> 灰 | G34: 10305413 | H34: A3228630T | I34: 5OET005693XCHNEA | J34: 532 | K34: 42 | L34: =K34/J34 -> 0.078947368 | M34: 32 | N34: 10 | P34: E4.5關(排風全開)、E2E3後段40
A35: 46027 | B35: 0.58402778 | C35: 46029 | D35: =RIGHT(I35,3) -> NXW | E35: =VLOOKUP(D:D,工作表2!A:B,2,0) -> 邦善 | F35: =VLOOKUP(D:D,工作表2!A:C,3,0) -> 白 | G35: 10304230 | H35: A32286G0T | I35: 5OET005693XCHNXW | J35: 420 | K35: 22 | L35: =K35/J35 -> 0.052380952 | M35: 17 | N35: 5 | P35: E4.5關(排風全開)、E2E3後段40
A36: 46027 | B36: 0.57916667 | C36: 46029 | D36: =RIGHT(I36,3) -> VPL | E36: =VLOOKUP(D:D,工作表2!A:B,2,0) -> 邦善 | F36: =VLOOKUP(D:D,工作表2!A:C,3,0) -> 藍 | G36: 10304229 | H36: A32286A1T | I36: 5OET005693XCHVPL | J36: 798 | K36: 42 | L36: =K36/J36 -> 0.052631579 | M36: 35 | N36: 7 | P36: E4.5關(排風全開)、E2E3後段40
A37: 46027 | B37: 0.62291667 | C37: 46029 | D37: =RIGHT(I37,3) -> WNS | E37: =VLOOKUP(D:D,工作表2!A:B,2,0) -> 邦善 | F37: =VLOOKUP(D:D,工作表2!A:C,3,0) -> 銀 | G37: 10310307 | H37: A3225022T | I37: 5OET005831XAHWNS | J37: 40 | K37: 5 | L37: =K37/J37 -> 0.125 | M37: 3 | N37: 2 | P37: E4.5關(排風全開)、E2E3後段40
A38: 46028 | B38: 0.61805556 | C38: 46029 | D38: =RIGHT(I38,3) -> NGW | E38: =VLOOKUP(D:D,工作表2!A:B,2,0) -> 邦善 | F38: =VLOOKUP(D:D,工作表2!A:C,3,0) -> 白 | G38: 10304245 | H38: A3280010T | I38: 5PPG007028XA0NGW | J38: 560 | K38: 77 | L38: =K38/J38 -> 0.1375 | M38: 50 | N38: 27 | P38: E4.5關(排風全開)、E2E3後段40 | Q38: L
A39: 46027 | B39: 0.58680556 | C39: 46029 | D39: =RIGHT(I39,3) -> RRA | E39: =VLOOKUP(D:D,工作表2!A:B,2,0) -> 邦善 | F39: =VLOOKUP(D:D,工作表2!A:C,3,0) -> 灰 | G39: 10304253 | H39: A3297950T | I39: 5PPG007033XA0RRA | J39: 240 | K39: 24 | L39: =K39/J39 -> 0.1 | M39: 20 | N39: 4 | P39: E4.5關(排風全開)、E2E3後段40
A40: 46024 | B40: 0.57916667 | C40: 46029 | D40: =RIGHT(I40,3) -> SYL | E40: =VLOOKUP(D:D,工作表2!A:B,2,0) -> 邦善 | F40: =VLOOKUP(D:D,工作表2!A:C,3,0) -> 藍 | G40: 10304250 | H40: A3297770T | I40: 5PPG007034XA0SYL | J40: 240 | K40: 6 | L40: =K40/J40 -> 0.025 | M40: 4 | N40: 2 | P40: E4.5關(排風全開)、E2E3後段40
A41: 46024 | B41: 0.5375 | C41: 46029 | D41: =RIGHT(I41,3) -> NGW | E41: =VLOOKUP(D:D,工作表2!A:B,2,0) -> 邦善 | F41: =VLOOKUP(D:D,工作表2!A:C,3,0) -> 白 | G41: 10304248 | H41: A3297520T | I41: 5PPG007036XA0NGW | J41: 400 | K41: 29 | L41: =K41/J41 -> 0.0725 | M41: 17 | N41: 3 | P41: E4.5關(排風全開)、E2E3後段40、內圍毛邊 | Q41: R | R41: 9
...

Sheet 工作表6
A1: 日期 | B1: 工單數 | C1: 不良數 | D1: 不良率 | E1: 5OE | F1: 5PP | G1: 5SN
A2: 46082 | B2: =SUMIF('塗裝各項不良率-明細'!C:C,工作表6!A:A,'塗裝各項不良率-明細'!J:J) -> 0 | C2: =SUMIF('塗裝各項不良率-明細'!C:C,工作表6!A:A,'塗裝各項不良率-明細'!K:K) -> 0 | D2: =C2/B2% -> #DIV/0! | E2: =IFERROR(SUMIFS('塗裝各項不良率-明細'!K:K, '塗裝各項不良率-明細'!C:C, A2, '塗裝各項不良率-明細'!I:I, "5OE*") / SUMIFS('塗裝各項不良率-明細'!J:J, '塗裝各項不良率-明細'!C:C, A2, '塗裝各項不良率-明細'!I:I, "5OE*"), 0) -> 0 | F2: =IFERROR(SUMIFS('塗裝各項不良率-明細'!K:K, '塗裝各項不良率-明細'!C:C, A2, '塗裝各項不良率-明細'!I:I, "5PP*") / SUMIFS('塗裝各項不良率-明細'!J:J, '塗裝各項不良率-明細'!C:C, A2, '塗裝各項不良率-明細'!I:I, "5PP*"), 0) -> 0 | G2: =IFERROR(SUMIFS('塗裝各項不良率-明細'!K:K, '塗裝各項不良率-明細'!C:C, A2, '塗裝各項不良率-明細'!I:I, "5SN*") / SUMIFS('塗裝各項不良率-明細'!J:J, '塗裝各項不良率-明細'!C:C, A2, '塗裝各項不良率-明細'!I:I, "5SN*"), 0) -> 0
A3: 46083 | B3: =SUMIF('塗裝各項不良率-明細'!C:C,工作表6!A:A,'塗裝各項不良率-明細'!J:J) -> 27358 | C3: =SUMIF('塗裝各項不良率-明細'!C:C,工作表6!A:A,'塗裝各項不良率-明細'!K:K) -> 2019 | D3: =C3/B3% -> 7.3799254 | E3: =IFERROR(SUMIFS('塗裝各項不良率-明細'!K:K, '塗裝各項不良率-明細'!C:C, A3, '塗裝各項不良率-明細'!I:I, "5OE*") / SUMIFS('塗裝各項不良率-明細'!J:J, '塗裝各項不良率-明細'!C:C, A3, '塗裝各項不良率-明細'!I:I, "5OE*"), 0) -> 0.071617818 | F3: =IFERROR(SUMIFS('塗裝各項不良率-明細'!K:K, '塗裝各項不良率-明細'!C:C, A3, '塗裝各項不良率-明細'!I:I, "5PP*") / SUMIFS('塗裝各項不良率-明細'!J:J, '塗裝各項不良率-明細'!C:C, A3, '塗裝各項不良率-明細'!I:I, "5PP*"), 0) -> 0.09025609 | G3: =IFERROR(SUMIFS('塗裝各項不良率-明細'!K:K, '塗裝各項不良率-明細'!C:C, A3, '塗裝各項不良率-明細'!I:I, "5SN*") / SUMIFS('塗裝各項不良率-明細'!J:J, '塗裝各項不良率-明細'!C:C, A3, '塗裝各項不良率-明細'!I:I, "5SN*"), 0) -> 0
A4: 46084 | B4: =SUMIF('塗裝各項不良率-明細'!C:C,工作表6!A:A,'塗裝各項不良率-明細'!J:J) -> 39958 | C4: =SUMIF('塗裝各項不良率-明細'!C:C,工作表6!A:A,'塗裝各項不良率-明細'!K:K) -> 1913 | D4: =C4/B4% -> 4.7875269 | E4: =IFERROR(SUMIFS('塗裝各項不良率-明細'!K:K, '塗裝各項不良率-明細'!C:C, A4, '塗裝各項不良率-明細'!I:I, "5OE*") / SUMIFS('塗裝各項不良率-明細'!J:J, '塗裝各項不良率-明細'!C:C, A4, '塗裝各項不良率-明細'!I:I, "5OE*"), 0) -> 0.044981334 | F4: =IFERROR(SUMIFS('塗裝各項不良率-明細'!K:K, '塗裝各項不良率-明細'!C:C, A4, '塗裝各項不良率-明細'!I:I, "5PP*") / SUMIFS('塗裝各項不良率-明細'!J:J, '塗裝各項不良率-明細'!C:C, A4, '塗裝各項不良率-明細'!I:I, "5PP*"), 0) -> 0.10706522 | G4: =IFERROR(SUMIFS('塗裝各項不良率-明細'!K:K, '塗裝各項不良率-明細'!C:C, A4, '塗裝各項不良率-明細'!I:I, "5SN*") / SUMIFS('塗裝各項不良率-明細'!J:J, '塗裝各項不良率-明細'!C:C, A4, '塗裝各項不良率-明細'!I:I, "5SN*"), 0) -> 0.0625
A5: 46085 | B5: =SUMIF('塗裝各項不良率-明細'!C:C,工作表6!A:A,'塗裝各項不良率-明細'!J:J) -> 46460 | C5: =SUMIF('塗裝各項不良率-明細'!C:C,工作表6!A:A,'塗裝各項不良率-明細'!K:K) -> 2749 | D5: =C5/B5% -> 5.9169178 | E5: =IFERROR(SUMIFS('塗裝各項不良率-明細'!K:K, '塗裝各項不良率-明細'!C:C, A5, '塗裝各項不良率-明細'!I:I, "5OE*") / SUMIFS('塗裝各項不良率-明細'!J:J, '塗裝各項不良率-明細'!C:C, A5, '塗裝各項不良率-明細'!I:I, "5OE*"), 0) -> 0.055855233 | F5: =IFERROR(SUMIFS('塗裝各項不良率-明細'!K:K, '塗裝各項不良率-明細'!C:C, A5, '塗裝各項不良率-明細'!I:I, "5PP*") / SUMIFS('塗裝各項不良率-明細'!J:J, '塗裝各項不良率-明細'!C:C, A5, '塗裝各項不良率-明細'!I:I, "5PP*"), 0) -> 0.10584416 | G5: =IFERROR(SUMIFS('塗裝各項不良率-明細'!K:K, '塗裝各項不良率-明細'!C:C, A5, '塗裝各項不良率-明細'!I:I, "5SN*") / SUMIFS('塗裝各項不良率-明細'!J:J, '塗裝各項不良率-明細'!C:C, A5, '塗裝各項不良率-明細'!I:I, "5SN*"), 0) -> 0
A6: 46086 | B6: =SUMIF('塗裝各項不良率-明細'!C:C,工作表6!A:A,'塗裝各項不良率-明細'!J:J) -> 35484 | C6: =SUMIF('塗裝各項不良率-明細'!C:C,工作表6!A:A,'塗裝各項不良率-明細'!K:K) -> 1819 | D6: =C6/B6% -> 5.1262541 | E6: =IFERROR(SUMIFS('塗裝各項不良率-明細'!K:K, '塗裝各項不良率-明細'!C:C, A6, '塗裝各項不良率-明細'!I:I, "5OE*") / SUMIFS('塗裝各項不良率-明細'!J:J, '塗裝各項不良率-明細'!C:C, A6, '塗裝各項不良率-明細'!I:I, "5OE*"), 0) -> 0.037454748 | F6: =IFERROR(SUMIFS('塗裝各項不良率-明細'!K:K, '塗裝各項不良率-明細'!C:C, A6, '塗裝各項不良率-明細'!I:I, "5PP*") / SUMIFS('塗裝各項不良率-明細'!J:J, '塗裝各項不良率-明細'!C:C, A6, '塗裝各項不良率-明細'!I:I, "5PP*"), 0) -> 0.10997632 | G6: =IFERROR(SUMIFS('塗裝各項不良率-明細'!K:K, '塗裝各項不良率-明細'!C:C, A6, '塗裝各項不良率-明細'!I:I, "5SN*") / SUMIFS('塗裝各項不良率-明細'!J:J, '塗裝各項不良率-明細'!C:C, A6, '塗裝各項不良率-明細'!I:I, "5SN*"), 0) -> 0
A7: 46087 | B7: =SUMIF('塗裝各項不良率-明細'!C:C,工作表6!A:A,'塗裝各項不良率-明細'!J:J) -> 32684 | C7: =SUMIF('塗裝各項不良率-明細'!C:C,工作表6!A:A,'塗裝各項不良率-明細'!K:K) -> 1274 | D7: =C7/B7% -> 3.8979317 | E7: =IFERROR(SUMIFS('塗裝各項不良率-明細'!K:K, '塗裝各項不良率-明細'!C:C, A7, '塗裝各項不良率-明細'!I:I, "5OE*") / SUMIFS('塗裝各項不良率-明細'!J:J, '塗裝各項不良率-明細'!C:C, A7, '塗裝各項不良率-明細'!I:I, "5OE*"), 0) -> 0.034752766 | F7: =IFERROR(SUMIFS('塗裝各項不良率-明細'!K:K, '塗裝各項不良率-明細'!C:C, A7, '塗裝各項不良率-明細'!I:I, "5PP*") / SUMIFS('塗裝各項不良率-明細'!J:J, '塗裝各項不良率-明細'!C:C, A7, '塗裝各項不良率-明細'!I:I, "5PP*"), 0) -> 0.087822014 | G7: =IFERROR(SUMIFS('塗裝各項不良率-明細'!K:K, '塗裝各項不良率-明細'!C:C, A7, '塗裝各項不良率-明細'!I:I, "5SN*") / SUMIFS('塗裝各項不良率-明細'!J:J, '塗裝各項不良率-明細'!C:C, A7, '塗裝各項不良率-明細'!I:I, "5SN*"), 0) -> 0.054545455
A8: 46088 | B8: =SUMIF('塗裝各項不良率-明細'!C:C,工作表6!A:A,'塗裝各項不良率-明細'!J:J) -> 0 | C8: =SUMIF('塗裝各項不良率-明細'!C:C,工作表6!A:A,'塗裝各項不良率-明細'!K:K) -> 0 | D8: =C8/B8% -> #DIV/0! | E8: =IFERROR(SUMIFS('塗裝各項不良率-明細'!K:K, '塗裝各項不良率-明細'!C:C, A8, '塗裝各項不良率-明細'!I:I, "5OE*") / SUMIFS('塗裝各項不良率-明細'!J:J, '塗裝各項不良率-明細'!C:C, A8, '塗裝各項不良率-明細'!I:I, "5OE*"), 0) -> 0 | F8: =IFERROR(SUMIFS('塗裝各項不良率-明細'!K:K, '塗裝各項不良率-明細'!C:C, A8, '塗裝各項不良率-明細'!I:I, "5PP*") / SUMIFS('塗裝各項不良率-明細'!J:J, '塗裝各項不良率-明細'!C:C, A8, '塗裝各項不良率-明細'!I:I, "5PP*"), 0) -> 0 | G8: =IFERROR(SUMIFS('塗裝各項不良率-明細'!K:K, '塗裝各項不良率-明細'!C:C, A8, '塗裝各項不良率-明細'!I:I, "5SN*") / SUMIFS('塗裝各項不良率-明細'!J:J, '塗裝各項不良率-明細'!C:C, A8, '塗裝各項不良率-明細'!I:I, "5SN*"), 0) -> 0
A9: 46089 | B9: =SUMIF('塗裝各項不良率-明細'!C:C,工作表6!A:A,'塗裝各項不良率-明細'!J:J) -> 0 | C9: =SUMIF('塗裝各項不良率-明細'!C:C,工作表6!A:A,'塗裝各項不良率-明細'!K:K) -> 0 | D9: =C9/B9% -> #DIV/0! | E9: =IFERROR(SUMIFS('塗裝各項不良率-明細'!K:K, '塗裝各項不良率-明細'!C:C, A9, '塗裝各項不良率-明細'!I:I, "5OE*") / SUMIFS('塗裝各項不良率-明細'!J:J, '塗裝各項不良率-明細'!C:C, A9, '塗裝各項不良率-明細'!I:I, "5OE*"), 0) -> 0 | F9: =IFERROR(SUMIFS('塗裝各項不良率-明細'!K:K, '塗裝各項不良率-明細'!C:C, A9, '塗裝各項不良率-明細'!I:I, "5PP*") / SUMIFS('塗裝各項不良率-明細'!J:J, '塗裝各項不良率-明細'!C:C, A9, '塗裝各項不良率-明細'!I:I, "5PP*"), 0) -> 0 | G9: =IFERROR(SUMIFS('塗裝各項不良率-明細'!K:K, '塗裝各項不良率-明細'!C:C, A9, '塗裝各項不良率-明細'!I:I, "5SN*") / SUMIFS('塗裝各項不良率-明細'!J:J, '塗裝各項不良率-明細'!C:C, A9, '塗裝各項不良率-明細'!I:I, "5SN*"), 0) -> 0
A10: 46090 | B10: =SUMIF('塗裝各項不良率-明細'!C:C,工作表6!A:A,'塗裝各項不良率-明細'!J:J) -> 31932 | C10: =SUMIF('塗裝各項不良率-明細'!C:C,工作表6!A:A,'塗裝各項不良率-明細'!K:K) -> 861 | D10: =C10/B10% -> 2.6963548 | E10: =IFERROR(SUMIFS('塗裝各項不良率-明細'!K:K, '塗裝各項不良率-明細'!C:C, A10, '塗裝各項不良率-明細'!I:I, "5OE*") / SUMIFS('塗裝各項不良率-明細'!J:J, '塗裝各項不良率-明細'!C:C, A10, '塗裝各項不良率-明細'!I:I, "5OE*"), 0) -> 0.026562698 | F10: =IFERROR(SUMIFS('塗裝各項不良率-明細'!K:K, '塗裝各項不良率-明細'!C:C, A10, '塗裝各項不良率-明細'!I:I, "5PP*") / SUMIFS('塗裝各項不良率-明細'!J:J, '塗裝各項不良率-明細'!C:C, A10, '塗裝各項不良率-明細'!I:I, "5PP*"), 0) -> 0.059895833 | G10: =IFERROR(SUMIFS('塗裝各項不良率-明細'!K:K, '塗裝各項不良率-明細'!C:C, A10, '塗裝各項不良率-明細'!I:I, "5SN*") / SUMIFS('塗裝各項不良率-明細'!J:J, '塗裝各項不良率-明細'!C:C, A10, '塗裝各項不良率-明細'!I:I, "5SN*"), 0) -> 0
A11: 46091 | B11: =SUMIF('塗裝各項不良率-明細'!C:C,工作表6!A:A,'塗裝各項不良率-明細'!J:J) -> 33308 | C11: =SUMIF('塗裝各項不良率-明細'!C:C,工作表6!A:A,'塗裝各項不良率-明細'!K:K) -> 1988 | D11: =C11/B11% -> 5.9685361 | E11: =IFERROR(SUMIFS('塗裝各項不良率-明細'!K:K, '塗裝各項不良率-明細'!C:C, A11, '塗裝各項不良率-明細'!I:I, "5OE*") / SUMIFS('塗裝各項不良率-明細'!J:J, '塗裝各項不良率-明細'!C:C, A11, '塗裝各項不良率-明細'!I:I, "5OE*"), 0) -> 0.058998356 | F11: =IFERROR(SUMIFS('塗裝各項不良率-明細'!K:K, '塗裝各項不良率-明細'!C:C, A11, '塗裝各項不良率-明細'!I:I, "5PP*") / SUMIFS('塗裝各項不良率-明細'!J:J, '塗裝各項不良率-明細'!C:C, A11, '塗裝各項不良率-明細'!I:I, "5PP*"), 0) -> 0.072619048 | G11: =IFERROR(SUMIFS('塗裝各項不良率-明細'!K:K, '塗裝各項不良率-明細'!C:C, A11, '塗裝各項不良率-明細'!I:I, "5SN*") / SUMIFS('塗裝各項不良率-明細'!J:J, '塗裝各項不良率-明細'!C:C, A11, '塗裝各項不良率-明細'!I:I, "5SN*"), 0) -> 0
A12: 46092 | B12: =SUMIF('塗裝各項不良率-明細'!C:C,工作表6!A:A,'塗裝各項不良率-明細'!J:J) -> 36418 | C12: =SUMIF('塗裝各項不良率-明細'!C:C,工作表6!A:A,'塗裝各項不良率-明細'!K:K) -> 1860 | D12: =C12/B12% -> 5.1073645 | E12: =IFERROR(SUMIFS('塗裝各項不良率-明細'!K:K, '塗裝各項不良率-明細'!C:C, A12, '塗裝各項不良率-明細'!I:I, "5OE*") / SUMIFS('塗裝各項不良率-明細'!J:J, '塗裝各項不良率-明細'!C:C, A12, '塗裝各項不良率-明細'!I:I, "5OE*"), 0) -> 0.050087625 | F12: =IFERROR(SUMIFS('塗裝各項不良率-明細'!K:K, '塗裝各項不良率-明細'!C:C, A12, '塗裝各項不良率-明細'!I:I, "5PP*") / SUMIFS('塗裝各項不良率-明細'!J:J, '塗裝各項不良率-明細'!C:C, A12, '塗裝各項不良率-明細'!I:I, "5PP*"), 0) -> 0.084615385 | G12: =IFERROR(SUMIFS('塗裝各項不良率-明細'!K:K, '塗裝各項不良率-明細'!C:C, A12, '塗裝各項不良率-明細'!I:I, "5SN*") / SUMIFS('塗裝各項不良率-明細'!J:J, '塗裝各項不良率-明細'!C:C, A12, '塗裝各項不良率-明細'!I:I, "5SN*"), 0) -> 0
A13: 46093 | B13: =SUMIF('塗裝各項不良率-明細'!C:C,工作表6!A:A,'塗裝各項不良率-明細'!J:J) -> 47474 | C13: =SUMIF('塗裝各項不良率-明細'!C:C,工作表6!A:A,'塗裝各項不良率-明細'!K:K) -> 2507 | D13: =C13/B13% -> 5.2807853 | E13: =IFERROR(SUMIFS('塗裝各項不良率-明細'!K:K, '塗裝各項不良率-明細'!C:C, A13, '塗裝各項不良率-明細'!I:I, "5OE*") / SUMIFS('塗裝各項不良率-明細'!J:J, '塗裝各項不良率-明細'!C:C, A13, '塗裝各項不良率-明細'!I:I, "5OE*"), 0) -> 0.046224109 | F13: =IFERROR(SUMIFS('塗裝各項不良率-明細'!K:K, '塗裝各項不良率-明細'!C:C, A13, '塗裝各項不良率-明細'!I:I, "5PP*") / SUMIFS('塗裝各項不良率-明細'!J:J, '塗裝各項不良率-明細'!C:C, A13, '塗裝各項不良率-明細'!I:I, "5PP*"), 0) -> 0.12208738 | G13: =IFERROR(SUMIFS('塗裝各項不良率-明細'!K:K, '塗裝各項不良率-明細'!C:C, A13, '塗裝各項不良率-明細'!I:I, "5SN*") / SUMIFS('塗裝各項不良率-明細'!J:J, '塗裝各項不良率-明細'!C:C, A13, '塗裝各項不良率-明細'!I:I, "5SN*"), 0) -> 0
... A126: 46203 | B126: =SUMIF('塗裝各項不良率-明細'!C:C,工作表6!A:A,'塗裝各項不良率-明細'!J:J) -> 0 | C126: =SUMIF('塗裝各項不良率-明細'!C:C,工作表6!A:A,'塗裝各項不良率-明細'!K:K) -> 0 | D126: =C126/B126% -> #DIV/0! | E126: =IFERROR(SUMIFS('塗裝各項不良率-明細'!K:K, '塗裝各項不良率-明細'!C:C, A126, '塗裝各項不良率-明細'!I:I, "5OE*") / SUMIFS('塗裝各項不良率-明細'!J:J, '塗裝各項不良率-明細'!C:C, A126, '塗裝各項不良率-明細'!I:I, "5OE*"), 0) -> 0 | F126: =IFERROR(SUMIFS('塗裝各項不良率-明細'!K:K, '塗裝各項不良率-明細'!C:C, A126, '塗裝各項不良率-明細'!I:I, "5PP*") / SUMIFS('塗裝各項不良率-明細'!J:J, '塗裝各項不良率-明細'!C:C, A126, '塗裝各項不良率-明細'!I:I, "5PP*"), 0) -> 0 | G126: =IFERROR(SUMIFS('塗裝各項不良率-明細'!K:K, '塗裝各項不良率-明細'!C:C, A126, '塗裝各項不良率-明細'!I:I, "5SN*") / SUMIFS('塗裝各項不良率-明細'!J:J, '塗裝各項不良率-明細'!C:C, A126, '塗裝各項不良率-明細'!I:I, "5SN*"), 0) -> 0
B128: =SUMIF('塗裝各項不良率-明細'!C:C,工作表6!A:A,'塗裝各項不良率-明細'!J:J) -> 0 | C128: =SUMIF('塗裝各項不良率-明細'!C:C,工作表6!A:A,'塗裝各項不良率-明細'!K:K) -> 0 | D128: =C128/B128% -> #DIV/0! | E128: =IFERROR(SUMIFS('塗裝各項不良率-明細'!K:K, '塗裝各項不良率-明細'!C:C, A128, '塗裝各項不良率-明細'!I:I, "5OE*") / SUMIFS('塗裝各項不良率-明細'!J:J, '塗裝各項不良率-明細'!C:C, A128, '塗裝各項不良率-明細'!I:I, "5OE*"), 0) -> 0 | F128: =IFERROR(SUMIFS('塗裝各項不良率-明細'!K:K, '塗裝各項不良率-明細'!C:C, A128, '塗裝各項不良率-明細'!I:I, "5PP*") / SUMIFS('塗裝各項不良率-明細'!J:J, '塗裝各項不良率-明細'!C:C, A128, '塗裝各項不良率-明細'!I:I, "5PP*"), 0) -> 0 | G128: =IFERROR(SUMIFS('塗裝各項不良率-明細'!K:K, '塗裝各項不良率-明細'!C:C, A128, '塗裝各項不良率-明細'!I:I, "5SN*") / SUMIFS('塗裝各項不良率-明細'!J:J, '塗裝各項不良率-明細'!C:C, A128, '塗裝各項不良率-明細'!I:I, "5SN*"), 0) -> 0
B129: =SUMIF('塗裝各項不良率-明細'!C:C,工作表6!A:A,'塗裝各項不良率-明細'!J:J) -> 0 | C129: =SUMIF('塗裝各項不良率-明細'!C:C,工作表6!A:A,'塗裝各項不良率-明細'!K:K) -> 0 | D129: =C129/B129% -> #DIV/0! | E129: =IFERROR(SUMIFS('塗裝各項不良率-明細'!K:K, '塗裝各項不良率-明細'!C:C, A129, '塗裝各項不良率-明細'!I:I, "5OE*") / SUMIFS('塗裝各項不良率-明細'!J:J, '塗裝各項不良率-明細'!C:C, A129, '塗裝各項不良率-明細'!I:I, "5OE*"), 0) -> 0 | F129: =IFERROR(SUMIFS('塗裝各項不良率-明細'!K:K, '塗裝各項不良率-明細'!C:C, A129, '塗裝各項不良率-明細'!I:I, "5PP*") / SUMIFS('塗裝各項不良率-明細'!J:J, '塗裝各項不良率-明細'!C:C, A129, '塗裝各項不良率-明細'!I:I, "5PP*"), 0) -> 0 | G129: =IFERROR(SUMIFS('塗裝各項不良率-明細'!K:K, '塗裝各項不良率-明細'!C:C, A129, '塗裝各項不良率-明細'!I:I, "5SN*") / SUMIFS('塗裝各項不良率-明細'!J:J, '塗裝各項不良率-明細'!C:C, A129, '塗裝各項不良率-明細'!I:I, "5SN*"), 0) -> 0
B130: =SUMIF('塗裝各項不良率-明細'!C:C,工作表6!A:A,'塗裝各項不良率-明細'!J:J) -> 0 | C130: =SUMIF('塗裝各項不良率-明細'!C:C,工作表6!A:A,'塗裝各項不良率-明細'!K:K) -> 0 | D130: =C130/B130% -> #DIV/0! | E130: =IFERROR(SUMIFS('塗裝各項不良率-明細'!K:K, '塗裝各項不良率-明細'!C:C, A130, '塗裝各項不良率-明細'!I:I, "5OE*") / SUMIFS('塗裝各項不良率-明細'!J:J, '塗裝各項不良率-明細'!C:C, A130, '塗裝各項不良率-明細'!I:I, "5OE*"), 0) -> 0 | F130: =IFERROR(SUMIFS('塗裝各項不良率-明細'!K:K, '塗裝各項不良率-明細'!C:C, A130, '塗裝各項不良率-明細'!I:I, "5PP*") / SUMIFS('塗裝各項不良率-明細'!J:J, '塗裝各項不良率-明細'!C:C, A130, '塗裝各項不良率-明細'!I:I, "5PP*"), 0) -> 0 | G130: =IFERROR(SUMIFS('塗裝各項不良率-明細'!K:K, '塗裝各項不良率-明細'!C:C, A130, '塗裝各項不良率-明細'!I:I, "5SN*") / SUMIFS('塗裝各項不良率-明細'!J:J, '塗裝各項不良率-明細'!C:C, A130, '塗裝各項不良率-明細'!I:I, "5SN*"), 0) -> 0
B131: =SUMIF('塗裝各項不良率-明細'!C:C,工作表6!A:A,'塗裝各項不良率-明細'!J:J) -> 0 | C131: =SUMIF('塗裝各項不良率-明細'!C:C,工作表6!A:A,'塗裝各項不良率-明細'!K:K) -> 0 | D131: =C131/B131% -> #DIV/0! | E131: =IFERROR(SUMIFS('塗裝各項不良率-明細'!K:K, '塗裝各項不良率-明細'!C:C, A131, '塗裝各項不良率-明細'!I:I, "5OE*") / SUMIFS('塗裝各項不良率-明細'!J:J, '塗裝各項不良率-明細'!C:C, A131, '塗裝各項不良率-明細'!I:I, "5OE*"), 0) -> 0 | F131: =IFERROR(SUMIFS('塗裝各項不良率-明細'!K:K, '塗裝各項不良率-明細'!C:C, A131, '塗裝各項不良率-明細'!I:I, "5PP*") / SUMIFS('塗裝各項不良率-明細'!J:J, '塗裝各項不良率-明細'!C:C, A131, '塗裝各項不良率-明細'!I:I, "5PP*"), 0) -> 0 | G131: =IFERROR(SUMIFS('塗裝各項不良率-明細'!K:K, '塗裝各項不良率-明細'!C:C, A131, '塗裝各項不良率-明細'!I:I, "5SN*") / SUMIFS('塗裝各項不良率-明細'!J:J, '塗裝各項不良率-明細'!C:C, A131, '塗裝各項不良率-明細'!I:I, "5SN*"), 0) -> 0
B132: =SUMIF('塗裝各項不良率-明細'!C:C,工作表6!A:A,'塗裝各項不良率-明細'!J:J) -> 0 | C132: =SUMIF('塗裝各項不良率-明細'!C:C,工作表6!A:A,'塗裝各項不良率-明細'!K:K) -> 0 | D132: =C132/B132% -> #DIV/0! | E132: =IFERROR(SUMIFS('塗裝各項不良率-明細'!K:K, '塗裝各項不良率-明細'!C:C, A132, '塗裝各項不良率-明細'!I:I, "5OE*") / SUMIFS('塗裝各項不良率-明細'!J:J, '塗裝各項不良率-明細'!C:C, A132, '塗裝各項不良率-明細'!I:I, "5OE*"), 0) -> 0 | F132: =IFERROR(SUMIFS('塗裝各項不良率-明細'!K:K, '塗裝各項不良率-明細'!C:C, A132, '塗裝各項不良率-明細'!I:I, "5PP*") / SUMIFS('塗裝各項不良率-明細'!J:J, '塗裝各項不良率-明細'!C:C, A132, '塗裝各項不良率-明細'!I:I, "5PP*"), 0) -> 0 | G132: =IFERROR(SUMIFS('塗裝各項不良率-明細'!K:K, '塗裝各項不良率-明細'!C:C, A132, '塗裝各項不良率-明細'!I:I, "5SN*") / SUMIFS('塗裝各項不良率-明細'!J:J, '塗裝各項不良率-明細'!C:C, A132, '塗裝各項不良率-明細'!I:I, "5SN*"), 0) -> 0
B133: =SUMIF('塗裝各項不良率-明細'!C:C,工作表6!A:A,'塗裝各項不良率-明細'!J:J) -> 0 | C133: =SUMIF('塗裝各項不良率-明細'!C:C,工作表6!A:A,'塗裝各項不良率-明細'!K:K) -> 0 | D133: =C133/B133% -> #DIV/0! | E133: =IFERROR(SUMIFS('塗裝各項不良率-明細'!K:K, '塗裝各項不良率-明細'!C:C, A133, '塗裝各項不良率-明細'!I:I, "5OE*") / SUMIFS('塗裝各項不良率-明細'!J:J, '塗裝各項不良率-明細'!C:C, A133, '塗裝各項不良率-明細'!I:I, "5OE*"), 0) -> 0 | F133: =IFERROR(SUMIFS('塗裝各項不良率-明細'!K:K, '塗裝各項不良率-明細'!C:C, A133, '塗裝各項不良率-明細'!I:I, "5PP*") / SUMIFS('塗裝各項不良率-明細'!J:J, '塗裝各項不良率-明細'!C:C, A133, '塗裝各項不良率-明細'!I:I, "5PP*"), 0) -> 0 | G133: =IFERROR(SUMIFS('塗裝各項不良率-明細'!K:K, '塗裝各項不良率-明細'!C:C, A133, '塗裝各項不良率-明細'!I:I, "5SN*") / SUMIFS('塗裝各項不良率-明細'!J:J, '塗裝各項不良率-明細'!C:C, A133, '塗裝各項不良率-明細'!I:I, "5SN*"), 0) -> 0
B134: =SUMIF('塗裝各項不良率-明細'!C:C,工作表6!A:A,'塗裝各項不良率-明細'!J:J) -> 0 | C134: =SUMIF('塗裝各項不良率-明細'!C:C,工作表6!A:A,'塗裝各項不良率-明細'!K:K) -> 0 | D134: =C134/B134% -> #DIV/0! | E134: =IFERROR(SUMIFS('塗裝各項不良率-明細'!K:K, '塗裝各項不良率-明細'!C:C, A134, '塗裝各項不良率-明細'!I:I, "5OE*") / SUMIFS('塗裝各項不良率-明細'!J:J, '塗裝各項不良率-明細'!C:C, A134, '塗裝各項不良率-明細'!I:I, "5OE*"), 0) -> 0 | F134: =IFERROR(SUMIFS('塗裝各項不良率-明細'!K:K, '塗裝各項不良率-明細'!C:C, A134, '塗裝各項不良率-明細'!I:I, "5PP*") / SUMIFS('塗裝各項不良率-明細'!J:J, '塗裝各項不良率-明細'!C:C, A134, '塗裝各項不良率-明細'!I:I, "5PP*"), 0) -> 0 | G134: =IFERROR(SUMIFS('塗裝各項不良率-明細'!K:K, '塗裝各項不良率-明細'!C:C, A134, '塗裝各項不良率-明細'!I:I, "5SN*") / SUMIFS('塗裝各項不良率-明細'!J:J, '塗裝各項不良率-明細'!C:C, A134, '塗裝各項不良率-明細'!I:I, "5SN*"), 0) -> 0
B135: =SUMIF('塗裝各項不良率-明細'!C:C,工作表6!A:A,'塗裝各項不良率-明細'!J:J) -> 0 | C135: =SUMIF('塗裝各項不良率-明細'!C:C,工作表6!A:A,'塗裝各項不良率-明細'!K:K) -> 0 | D135: =C135/B135% -> #DIV/0! | E135: =IFERROR(SUMIFS('塗裝各項不良率-明細'!K:K, '塗裝各項不良率-明細'!C:C, A135, '塗裝各項不良率-明細'!I:I, "5OE*") / SUMIFS('塗裝各項不良率-明細'!J:J, '塗裝各項不良率-明細'!C:C, A135, '塗裝各項不良率-明細'!I:I, "5OE*"), 0) -> 0 | F135: =IFERROR(SUMIFS('塗裝各項不良率-明細'!K:K, '塗裝各項不良率-明細'!C:C, A135, '塗裝各項不良率-明細'!I:I, "5PP*") / SUMIFS('塗裝各項不良率-明細'!J:J, '塗裝各項不良率-明細'!C:C, A135, '塗裝各項不良率-明細'!I:I, "5PP*"), 0) -> 0 | G135: =IFERROR(SUMIFS('塗裝各項不良率-明細'!K:K, '塗裝各項不良率-明細'!C:C, A135, '塗裝各項不良率-明細'!I:I, "5SN*") / SUMIFS('塗裝各項不良率-明細'!J:J, '塗裝各項不良率-明細'!C:C, A135, '塗裝各項不良率-明細'!I:I, "5SN*"), 0) -> 0
B136: =SUMIF('塗裝各項不良率-明細'!C:C,工作表6!A:A,'塗裝各項不良率-明細'!J:J) -> 0 | C136: =SUMIF('塗裝各項不良率-明細'!C:C,工作表6!A:A,'塗裝各項不良率-明細'!K:K) -> 0 | D136: =C136/B136% -> #DIV/0! | E136: =IFERROR(SUMIFS('塗裝各項不良率-明細'!K:K, '塗裝各項不良率-明細'!C:C, A136, '塗裝各項不良率-明細'!I:I, "5OE*") / SUMIFS('塗裝各項不良率-明細'!J:J, '塗裝各項不良率-明細'!C:C, A136, '塗裝各項不良率-明細'!I:I, "5OE*"), 0) -> 0 | F136: =IFERROR(SUMIFS('塗裝各項不良率-明細'!K:K, '塗裝各項不良率-明細'!C:C, A136, '塗裝各項不良率-明細'!I:I, "5PP*") / SUMIFS('塗裝各項不良率-明細'!J:J, '塗裝各項不良率-明細'!C:C, A136, '塗裝各項不良率-明細'!I:I, "5PP*"), 0) -> 0 | G136: =IFERROR(SUMIFS('塗裝各項不良率-明細'!K:K, '塗裝各項不良率-明細'!C:C, A136, '塗裝各項不良率-明細'!I:I, "5SN*") / SUMIFS('塗裝各項不良率-明細'!J:J, '塗裝各項不良率-明細'!C:C, A136, '塗裝各項不良率-明細'!I:I, "5SN*"), 0) -> 0
B137: =SUMIF('塗裝各項不良率-明細'!C:C,工作表6!A:A,'塗裝各項不良率-明細'!J:J) -> 0 | C137: =SUMIF('塗裝各項不良率-明細'!C:C,工作表6!A:A,'塗裝各項不良率-明細'!K:K) -> 0 | D137: =C137/B137% -> #DIV/0! | E137: =IFERROR(SUMIFS('塗裝各項不良率-明細'!K:K, '塗裝各項不良率-明細'!C:C, A137, '塗裝各項不良率-明細'!I:I, "5OE*") / SUMIFS('塗裝各項不良率-明細'!J:J, '塗裝各項不良率-明細'!C:C, A137, '塗裝各項不良率-明細'!I:I, "5OE*"), 0) -> 0 | F137: =IFERROR(SUMIFS('塗裝各項不良率-明細'!K:K, '塗裝各項不良率-明細'!C:C, A137, '塗裝各項不良率-明細'!I:I, "5PP*") / SUMIFS('塗裝各項不良率-明細'!J:J, '塗裝各項不良率-明細'!C:C, A137, '塗裝各項不良率-明細'!I:I, "5PP*"), 0) -> 0 | G137: =IFERROR(SUMIFS('塗裝各項不良率-明細'!K:K, '塗裝各項不良率-明細'!C:C, A137, '塗裝各項不良率-明細'!I:I, "5SN*") / SUMIFS('塗裝各項不良率-明細'!J:J, '塗裝各項不良率-明細'!C:C, A137, '塗裝各項不良率-明細'!I:I, "5SN*"), 0) -> 0
B138: =SUMIF('塗裝各項不良率-明細'!C:C,工作表6!A:A,'塗裝各項不良率-明細'!J:J) -> 0 | C138: =SUMIF('塗裝各項不良率-明細'!C:C,工作表6!A:A,'塗裝各項不良率-明細'!K:K) -> 0 | D138: =C138/B138% -> #DIV/0! | E138: =IFERROR(SUMIFS('塗裝各項不良率-明細'!K:K, '塗裝各項不良率-明細'!C:C, A138, '塗裝各項不良率-明細'!I:I, "5OE*") / SUMIFS('塗裝各項不良率-明細'!J:J, '塗裝各項不良率-明細'!C:C, A138, '塗裝各項不良率-明細'!I:I, "5OE*"), 0) -> 0 | F138: =IFERROR(SUMIFS('塗裝各項不良率-明細'!K:K, '塗裝各項不良率-明細'!C:C, A138, '塗裝各項不良率-明細'!I:I, "5PP*") / SUMIFS('塗裝各項不良率-明細'!J:J, '塗裝各項不良率-明細'!C:C, A138, '塗裝各項不良率-明細'!I:I, "5PP*"), 0) -> 0 | G138: =IFERROR(SUMIFS('塗裝各項不良率-明細'!K:K, '塗裝各項不良率-明細'!C:C, A138, '塗裝各項不良率-明細'!I:I, "5SN*") / SUMIFS('塗裝各項不良率-明細'!J:J, '塗裝各項不良率-明細'!C:C, A138, '塗裝各項不良率-明細'!I:I, "5SN*"), 0) -> 0
B139: =SUMIF('塗裝各項不良率-明細'!C:C,工作表6!A:A,'塗裝各項不良率-明細'!J:J) -> 0 | C139: =SUMIF('塗裝各項不良率-明細'!C:C,工作表6!A:A,'塗裝各項不良率-明細'!K:K) -> 0 | D139: =C139/B139% -> #DIV/0! | E139: =IFERROR(SUMIFS('塗裝各項不良率-明細'!K:K, '塗裝各項不良率-明細'!C:C, A139, '塗裝各項不良率-明細'!I:I, "5OE*") / SUMIFS('塗裝各項不良率-明細'!J:J, '塗裝各項不良率-明細'!C:C, A139, '塗裝各項不良率-明細'!I:I, "5OE*"), 0) -> 0 | F139: =IFERROR(SUMIFS('塗裝各項不良率-明細'!K:K, '塗裝各項不良率-明細'!C:C, A139, '塗裝各項不良率-明細'!I:I, "5PP*") / SUMIFS('塗裝各項不良率-明細'!J:J, '塗裝各項不良率-明細'!C:C, A139, '塗裝各項不良率-明細'!I:I, "5PP*"), 0) -> 0 | G139: =IFERROR(SUMIFS('塗裝各項不良率-明細'!K:K, '塗裝各項不良率-明細'!C:C, A139, '塗裝各項不良率-明細'!I:I, "5SN*") / SUMIFS('塗裝各項不良率-明細'!J:J, '塗裝各項不良率-明細'!C:C, A139, '塗裝各項不良率-明細'!I:I, "5SN*"), 0) -> 0
... B172: =SUMIF('塗裝各項不良率-明細'!C:C,工作表6!A:A,'塗裝各項不良率-明細'!J:J) -> 0 | C172: =SUMIF('塗裝各項不良率-明細'!C:C,工作表6!A:A,'塗裝各項不良率-明細'!K:K) -> 0 | D172: =C172/B172% -> #DIV/0! | E172: =IFERROR(SUMIFS('塗裝各項不良率-明細'!K:K, '塗裝各項不良率-明細'!C:C, A172, '塗裝各項不良率-明細'!I:I, "5OE*") / SUMIFS('塗裝各項不良率-明細'!J:J, '塗裝各項不良率-明細'!C:C, A172, '塗裝各項不良率-明細'!I:I, "5OE*"), 0) -> 0 | F172: =IFERROR(SUMIFS('塗裝各項不良率-明細'!K:K, '塗裝各項不良率-明細'!C:C, A172, '塗裝各項不良率-明細'!I:I, "5PP*") / SUMIFS('塗裝各項不良率-明細'!J:J, '塗裝各項不良率-明細'!C:C, A172, '塗裝各項不良率-明細'!I:I, "5PP*"), 0) -> 0 | G172: =IFERROR(SUMIFS('塗裝各項不良率-明細'!K:K, '塗裝各項不良率-明細'!C:C, A172, '塗裝各項不良率-明細'!I:I, "5SN*") / SUMIFS('塗裝各項不良率-明細'!J:J, '塗裝各項不良率-明細'!C:C, A172, '塗裝各項不良率-明細'!I:I, "5SN*"), 0) -> 0

Sheet 工作表2
A1: 1:邦善 | B1: 2.建榮 | C1: 3.敦陽 | F1: 霧面黑 | G1: 銀 | H1: 白 | I1: 灰 | J1: 紅 | K1: 黑 | L1: 藍 | M1: 綠 | N1: 金 | O1: 棕 | P1: 黃 | Q1: 紫 | R1: 橘
A2: 76S | B2: 敦陽 | C2: 銀 | D2: PT00047500T
A3: 4PW | B3: 敦陽 | C3: 白 | D3: PT00001700T
A4: 4VW | B4: 建榮 | C4: 白 | D4: PT00002100T
A5: 75W | B5: 敦陽 | C5: 白 | D5: PT00047400T
A6: 76S | B6: 敦陽 | C6: 銀 | D6: PT00047500T
A7: 78A | B7: 敦陽 | C7: 灰 | D7: PT00047600T
A8: 88S | B8: 敦陽 | C8: 銀 | D8: PT00048000T
A9: 9DB | B9: 敦陽 | C9: 黑 | D9: PT00015200T
A10: AAW | B10: 邦善 | C10: 白 | D10: PT00000800T
A11: FHW | B11: 建榮 | C11: 白 | D11: PT00050000T
A12: HSS | B12: 邦善 | C12: 銀 | D12: PT00111600T
A13: HUR | B13: 建榮 | C13: 紅 | D13: PT00111700T
... A59: HSS | B59: 邦善 | C59: 銀 | D59: PT00111600T
A60: A0T | B60: 建榮 | C60: 底漆
A61: MUB | B61: 邦善 | C61: 黑 | D61: PT00109500T
A62: QEN | B62: 邦善 | C62: 棕 | D62: PT00128600T
A63: V9L | B63: 邦善 | C63: 藍 | D63: PT00154100T
A64: 2US | B64: 建榮 | C64: 銀 | D64: PT00006700T
A65: M2W | B65: 邦善 | C65: 白 | D65: PT00105700T
A66: 71A | B66: 敦陽 | C66: 灰 | D66: PT00003000T
A67: CCA | B67: 邦善 | C67: 灰 | D67: PT00030800T
A68: 39A | B68: 敦陽 | C68: 灰 | D68: =VLOOKUP(A68,[2]色碼對照!$G:$I,3,0) -> #N/A
A69: 4BB | B69: 敦陽 | C69: 黑 | D69: =VLOOKUP(A69,[2]色碼對照!$G:$I,3,0) -> #N/A
A70: 7FB | B70: 邦善 | C70: 黑 | D70: =VLOOKUP(A70,[2]色碼對照!$G:$I,3,0) -> #N/A
A71: ACS | B71: 建榮 | C71: 銀 | D71: =VLOOKUP(A71,[2]色碼對照!$G:$I,3,0) -> #N/A
A72: 6XB | B72: 邦善 | C72: 霧面黑 | D72: =VLOOKUP(A72,[2]色碼對照!$G:$I,3,0) -> #N/A
A73: BBB | B73: 邦善 | C73: 霧面黑 | D73: =VLOOKUP(A73,[2]色碼對照!$G:$I,3,0) -> #N/A
A74: HDL | B74: 邦善 | C74: 藍 | D74: =VLOOKUP(A74,[2]色碼對照!$G:$I,3,0) -> #N/A
A75: QRB | B75: 邦善 | C75: 霧面黑
A76: 31B | B76: 建榮 | C76: 黑
A77: EEA | B77: 建榮 | C77: 灰
A78: N4L | B78: 邦善 | C78: 藍
A79: 09B | B79: 邦善 | C79: 黑
A80: VLS | B80: 邦善 | C80: 銀
A81: NJR | B81: 邦善 | C81: 紅
A82: S3B | B82: 邦善 | C82: 黑
A83: VBR | B83: 邦善 | C83: 紅
A84: QUW | B84: 邦善 | C84: 白
A85: QXR | B85: 邦善 | C85: 紅
...
